<?xml version="1.0" ?>
<!-- =================================================================================== -->
<!-- |    This document was autogenerated by xacro from limo_mecanum.xacro             | -->
<!-- |    EDITING THIS FILE BY HAND IS NOT RECOMMENDED                                 | -->
<!-- =================================================================================== -->
<robot name="limo_mecanum">
  <transmission name="front_right_wheel_trans" type="SimpleTransmission">
    <type>transmission_interface/SimpleTransmission</type>
    <actuator name="front_right_wheel_motor">
      <hardwareInterface>hardware_interface/VelocityJointInterface</hardwareInterface>
      <mechanicalReduction>1</mechanicalReduction>
    </actuator>
    <joint name="front_right_wheel">
      <hardwareInterface>hardware_interface/VelocityJointInterface</hardwareInterface>
    </joint>
  </transmission>
  <transmission name="front_left_wheel_trans" type="SimpleTransmission">
    <type>transmission_interface/SimpleTransmission</type>
    <actuator name="front_left_wheel_motor">
      <hardwareInterface>hardware_interface/VelocityJointInterface</hardwareInterface>
      <mechanicalReduction>1</mechanicalReduction>
    </actuator>
    <joint name="front_left_wheel">
      <hardwareInterface>hardware_interface/VelocityJointInterface</hardwareInterface>
    </joint>
  </transmission>
  <transmission name="rear_left_wheel_trans" type="SimpleTransmission">
    <type>transmission_interface/SimpleTransmission</type>
    <actuator name="rear_left_wheel_motor">
      <hardwareInterface>hardware_interface/VelocityJointInterface</hardwareInterface>
      <mechanicalReduction>1</mechanicalReduction>
    </actuator>
    <joint name="rear_left_wheel">
      <hardwareInterface>hardware_interface/VelocityJointInterface</hardwareInterface>
    </joint>
  </transmission>
  <transmission name="rear_right_wheel_trans" type="SimpleTransmission">
    <type>transmission_interface/SimpleTransmission</type>
    <actuator name="rear_right_wheel_motor">
      <hardwareInterface>hardware_interface/VelocityJointInterface</hardwareInterface>
      <mechanicalReduction>1</mechanicalReduction>
    </actuator>
    <joint name="rear_right_wheel">
      <hardwareInterface>hardware_interface/VelocityJointInterface</hardwareInterface>
    </joint>
  </transmission>
  <gazebo reference="laser_link">
    <sensor name="laser_sensor" type="ray">
      <pose>0 0 0 0 0 0</pose>
      <visualize>false</visualize>
      <update_rate>10</update_rate>
      <ray>
        <scan>
          <horizontal>
            <samples>399</samples>
            <resolution>1</resolution>
            <min_angle>-1.57079637051</min_angle>
            <max_angle>1.57079637051</max_angle>
          </horizontal>
        </scan>
        <range>
          <min>0.1</min>
          <max>12.0</max>
          <resolution>0.01</resolution>
        </range>
        <noise>
          <type>gaussian</type>
          <mean>0.0</mean>
          <stddev>0.01</stddev>
        </noise>
      </ray>
      <plugin filename="libgazebo_ros_laser.so" name="gazebo_ros_laser_sensor">
        <topicName>/scan</topicName>
        <frameName>laser_link</frameName>
      </plugin>
    </sensor>
  </gazebo>
  <gazebo reference="depth_camera_link">
    <sensor name="sensor_camera" type="depth">
      <pose>0.0 0.0 0.0 0.0 0.0 0.0</pose>
      <always_on>true</always_on>
      <visualize>true</visualize>
      <update_rate>10.0</update_rate>
      <camera name="head">
        <horizontal_fov>1.3962634</horizontal_fov>
        <image>
          <width>640</width>
          <height>480</height>
          <format>R8G8B8</format>
        </image>
        <clip>
          <near>0.02</near>
          <far>300</far>
        </clip>
      </camera>
      <plugin filename="libgazebo_ros_openni_kinect.so" name="gazebo_ros_depth_camera_sensor">
        <baseline>0.2</baseline>
        <alwaysOn>true</alwaysOn>
        <!-- Keep this zero, update_rate in the parent <sensor> tag
                will control the frame rate. -->
        <updateRate>0.0</updateRate>
        <cameraName>camera</cameraName>
        <imageTopicName>/camera/color/image_raw</imageTopicName>
        <cameraInfoTopicName>/camera/color/camera_info</cameraInfoTopicName>
        <depthImageTopicName>/camera/depth/image_raw</depthImageTopicName>
        <depthImageCameraInfoTopicName>/camera/depth/camera_info</depthImageCameraInfoTopicName>
        <pointCloudTopicName>/camera/depth/points</pointCloudTopicName>
        <frameName>depth_link</frameName>
        <pointCloudCutoff>0.5</pointCloudCutoff>
        <pointCloudCutoffMax>3.0</pointCloudCutoffMax>
        <distortionK1>0</distortionK1>
        <distortionK2>0</distortionK2>
        <distortionK3>0</distortionK3>
        <distortionT1>0</distortionT1>
        <distortionT2>0</distortionT2>
        <CxPrime>0</CxPrime>
        <Cx>0</Cx>
        <Cy>0</Cy>
        <focalLength>0</focalLength>
        <hackBaseline>0</hackBaseline>
      </plugin>
    </sensor>
  </gazebo>
  <gazebo reference="imu_link">
    <gravity>true</gravity>
    <sensor name="imu_sensor" type="imu">
      <always_on>true</always_on>
      <update_rate>100</update_rate>
      <visualize>true</visualize>
      <topic>__default_topic__</topic>
      <plugin filename="libgazebo_ros_imu_sensor.so" name="imu_plugin">
        <topicName>/imu</topicName>
        <bodyName>imu_link</bodyName>
        <updateRateHZ>100.0</updateRateHZ>
        <gaussianNoise>0.001</gaussianNoise>
        <xyzOffset>0 0 0</xyzOffset>
        <rpyOffset>0 0 0</rpyOffset>
        <frameName>imu_link</frameName>
      </plugin>
      <pose>0 0 0 0 0 0</pose>
    </sensor>
  </gazebo>
  <gazebo>
    <plugin filename="libgazebo_ros_control.so" name="gazebo_ros_control"/>
    <plugin filename="libgazebo_ros_planar_move.so" name="Mecanum_controller">
      <updateRate>20.0</updateRate>
      <odometryRate>20.0</odometryRate>
      <cmdTimeout>1.0</cmdTimeout>
      <leftFrontJoint>front_left_wheel</leftFrontJoint>
      <rightFrontJoint>front_right_wheel</rightFrontJoint>
      <leftRearJoint>rear_left_wheel</leftRearJoint>
      <rightRearJoint>rear_right_wheel</rightRearJoint>
      <wheelSeparation>0.172</wheelSeparation>
      <wheelDiameter>0.096</wheelDiameter>
      <robotBaseFrame>base_link</robotBaseFrame>
      <commandTopic>/limo/cmd_vel</commandTopic>
      <torque>500</torque>
      <broadcastTF>false</broadcastTF>
      <odometryTopic>odom</odometryTopic>
      <odometryFrame>odom</odometryFrame>
      <covariance_x>0.000100</covariance_x>
      <covariance_y>0.000100</covariance_y>
      <covariance_yaw>0.010000</covariance_yaw>
    </plugin>
  </gazebo>
  <link name="base_footprint"/>
  <joint name="base_joint" type="fixed">
    <parent link="base_link"/>
    <child link="base_footprint"/>
    <origin rpy="0 0 0" xyz="0.0 0.0 -0.15"/>
  </joint>
  <!-- Base link -->
  <link name="base_link">
    <visual>
      <origin rpy="0 0 1.57" xyz="0 0 -0.15"/>
      <geometry>
        <mesh filename="package://rubot_limo_description/meshes/limo_base.dae"/>
      </geometry>
    </visual>
    <collision>
      <origin rpy="0 0 1.57" xyz="0 0 -0.15"/>
      <geometry>
        <mesh filename="package://rubot_limo_description/meshes/limo_collision.stl"/>
      </geometry>
    </collision>
    <inertial>
      <origin xyz="0.0 0.0 0.0"/>
      <mass value="2.1557"/>
      <inertia ixx="0.019264" ixy="0" ixz="0" iyy="0.029586" iyz="0" izz="0.02693"/>
    </inertial>
  </link>
  <link name="laser_link"/>
  <joint name="laser_joint" type="fixed">
    <origin rpy="0 0 0" xyz="0.103 0 -0.034"/>
    <child link="laser_link"/>
    <parent link="base_link"/>
  </joint>
  <link name="depth_camera_link"/>
  <joint name="depth_camera_joint" type="fixed">
    <origin rpy="0 0 0" xyz="0.084 0 0.03"/>
    <child link="depth_camera_link"/>
    <parent link="base_link"/>
  </joint>
  <link name="depth_link"/>
  <joint name="depth_camera_to_camera_joint" type="fixed">
    <origin rpy="-1.570795 0 -1.570795 " xyz="0 0 0"/>
    <parent link="depth_camera_link"/>
    <child link="depth_link"/>
  </joint>
  <link name="imu_link"/>
  <joint name="imu_joint" type="fixed">
    <origin rpy="0 0 0" xyz="0.0 0 -0.1"/>
    <child link="imu_link"/>
    <parent link="base_link"/>
  </joint>
  <link name="front_left_wheel_link">
    <inertial>
      <origin xyz="0 0.022 0"/>
      <mass value="0.2"/>
      <inertia ixx="0.000147" ixy="0" ixz="0" iyy="0.00023" iyz="0" izz="0.000147"/>
    </inertial>
    <visual>
      <origin rpy="0 0 0" xyz="0 0 0"/>
      <geometry>
        <mesh filename="package://rubot_limo_description/meshes/limo_wheel.dae"/>
      </geometry>
    </visual>
    <collision>
      <origin rpy="1.57 0 0" xyz="0 0.02185 0"/>
      <geometry>
        <cylinder length="0.0437" radius="0.048"/>
      </geometry>
    </collision>
  </link>
  <joint name="front_left_wheel" type="continuous">
    <parent link="base_link"/>
    <child link="front_left_wheel_link"/>
    <origin rpy="0 0  0" xyz="0.1 0.065 -0.1"/>
    <axis xyz="0 1 0"/>
  </joint>
  <link name="front_right_wheel_link">
    <inertial>
      <origin xyz="0 0.022 0"/>
      <mass value="0.2"/>
      <inertia ixx="0.000147" ixy="0" ixz="0" iyy="0.00023" iyz="0" izz="0.000147"/>
    </inertial>
    <visual>
      <origin rpy="0 0 0" xyz="0 0 0"/>
      <geometry>
        <mesh filename="package://rubot_limo_description/meshes/limo_wheel.dae"/>
      </geometry>
    </visual>
    <collision>
      <origin rpy="1.57 0 0" xyz="0 0.02185 0"/>
      <geometry>
        <cylinder length="0.0437" radius="0.048"/>
      </geometry>
    </collision>
  </link>
  <joint name="front_right_wheel" type="continuous">
    <parent link="base_link"/>
    <child link="front_right_wheel_link"/>
    <origin rpy="3.14159 0 0" xyz="0.1 -0.065 -0.1"/>
    <axis xyz="0 -1 0"/>
  </joint>
  <link name="rear_left_wheel_link">
    <inertial>
      <origin xyz="0 0.022 0"/>
      <mass value="0.2"/>
      <inertia ixx="0.000147" ixy="0" ixz="0" iyy="0.00023" iyz="0" izz="0.000147"/>
    </inertial>
    <visual>
      <origin rpy="0 0 0" xyz="0 0 0"/>
      <geometry>
        <mesh filename="package://rubot_limo_description/meshes/limo_wheel.dae"/>
      </geometry>
    </visual>
    <collision>
      <origin rpy="1.57 0 0" xyz="0 0.02185 0"/>
      <geometry>
        <cylinder length="0.0437" radius="0.048"/>
      </geometry>
    </collision>
  </link>
  <joint name="rear_left_wheel" type="continuous">
    <parent link="base_link"/>
    <child link="rear_left_wheel_link"/>
    <origin rpy="0 0 0" xyz="-0.1 0.065 -0.1"/>
    <axis xyz="0 1 0"/>
  </joint>
  <link name="rear_right_wheel_link">
    <inertial>
      <origin xyz="0 0.022 0"/>
      <mass value="0.2"/>
      <inertia ixx="0.000147" ixy="0" ixz="0" iyy="0.00023" iyz="0" izz="0.000147"/>
    </inertial>
    <visual>
      <origin rpy="0 0 0" xyz="0 0 0"/>
      <geometry>
        <mesh filename="package://rubot_limo_description/meshes/limo_wheel.dae"/>
      </geometry>
    </visual>
    <collision>
      <origin rpy="1.57 0 0" xyz="0 0.02185 0"/>
      <geometry>
        <cylinder length="0.0437" radius="0.048"/>
      </geometry>
    </collision>
  </link>
  <joint name="rear_right_wheel" type="continuous">
    <parent link="base_link"/>
    <child link="rear_right_wheel_link"/>
    <origin rpy="3.14159 0 0" xyz="-0.1 -0.065 -0.1"/>
    <axis xyz="0 -1 0"/>
  </joint>
</robot>